Workbook

Sheet Information
A1: Case Study 2: Gasoline versus alternative fuel vehicles (due 4/21, 10 points)
A3: In the Proceedings of the National Academies of Sciences, Michalek et al. (2011) write: The electrification of passenger vehicles has the potential to address three of the most critical challenges of our time - (i) produce fewer greenhouse gas (GHG) emissions when powered by electricity instead of gasoline, depending on the electricity source; (ii) reduce tailpipe emissions, which impact people and the environment; and (iii) reduce gasoline consumption, helping to diminish dependency on imported oil. Recognizing these benefits, US policymakers have provided federal tax credits of up to $7,500 per vehicle to encourage electrified transportation, with additional supporting policies enacted in many states.
A5: Despite the societal benefits conferred by a wider adoption of electrified vehicles, people (like you and me) make decisions based on total ownership costs and pay little attention to environmental and energy security benefits. Therefore, I would like you to estimate total ownership costs for five different vehicle types: (a) conventional gasoline vehicle, (b) alternative fuel (e.g., E85 vehicle) (c) hybrid electric vehicle (HEV), (d) plug-in hybrid electric vehicle (PHEV), and (e) battery electric vehicle (BEV) and explore the uncertainty/variability in the cost estimates using a stochastic model. Total ownership costs should, at a minimum, include costs for the following:
A6: Vehicle and other upfront costs (e.g., auto loan)
A7: Fuel (note: electricity is a ‘fuel’)
A8: Battery (initial and replacement), home charger
A9: Scheduled maintenance (e.g., oil, tire rotation, and other consumables)
A10: Salvage
A11: Local/state/national credit for buying an electric vehicle
A13: The following questions (not exhaustive) should help you get started on the problem:
A14: What type of vehicle should you consider? 4-door sedan? SUV? 2-door coupe? Truck?
A15: Given your choice for a vehicle, what are the costs for a comparable conventional vehicle, alternative fuel vehicle, HEV, PHEV, and BEV? Here, comparable would mean similarity (not equivalence), in say performance, size, functionality, etc.
... A36: Michalek et al., PNAS, 2011: http://www.pnas.org/content/108/40/16554.short

Sheet Calculations
A1: 4-Door Sedan | C1: Upfront Costs
A2: Fuel Type | B2: Specific Vehicle Name/Brand | C2: Purchace Price [$] | D2: Loan Payment | E2: Battery Replacement Cost [$] | F2: Home Charger Cost [$] | G2: Fuel Capacity [gas] | H2: Fuel Capacity [kWh] | I2: Fuel Cost [$/Gal] | J2: Fuel Cost [$/kWh] | K2: Est. Range [miles] | L2: Calc Ann. Fuel Cost | M2: Annual Fuel Cost [$] | N2: Annual Maintenance [$] | O2: Local/State/National Credit [$] | P2: Vehicle Life Span [years] | Q2: Salvage Value [$] | R2: NPV [$]
A3: Gasoline | B3: 2024 Toyota Corolla LE | C3: 22000 | D3: =(C3-O3)*(($B$11)*(1+$B$11)^$B$12)/(((1+$B$11)^$B$12)-1) -> 418.74974 | E3: 112 | F3: 0 | G3: 13.2 | H3: 0 | I3: 3.3 | J3: 0 | K3: 450 | L3: =($B$18/K3)*((G3*I3)+(H3*J3)) -> 1384.24 | M3: 1500 | N3: 500 | O3: 0 | P3: 15 | Q3: 7700 | R3: ='NPV-Gas'!N4 -> -30770.265
A4: E85 | B4: 2024 Chevy Malibu | C4: 28000 | D4: =(C4-O4)*(($B$11)*(1+$B$11)^$B$12)/(((1+$B$11)^$B$12)-1) -> 532.95421 | E4: 112 | F4: 0 | G4: 15.8 | H4: 0 | I4: 2.5 | J4: 0 | K4: 550 | L4: =($B$18/K4)*((G4*I4)+(H4*J4)) -> 1027 | M4: 1800 | N4: 550 | O4: 0 | P4: 15 | Q4: 9800 | R4: ='NPV-E85'!N4 -> -34952.215
A5: HEV | B5: 2024 Honda Accord Hybrid Sport | C5: 32000 | D5: =(C5-O5)*(($B$11)*(1+$B$11)^$B$12)/(((1+$B$11)^$B$12)-1) -> 609.09053 | E5: 220.71 | F5: 1200 | G5: 12.8 | H5: 0 | I5: 3.3 | J5: 0 | K5: 614 | L5: =($B$18/K5)*((G5*I5)+(H5*J5)) -> 983.76547 | M5: 1200 | N5: 600 | O5: 0 | P5: 15 | Q5: 11200 | R5: ='NPV-HEV'!N4 -> -40003.087
A6: PHEV | B6: 2024 Hyundai Sonata Plug-in Hybrid | C6: 34000 | D6: =(C6-O6)*(($B$11)*(1+$B$11)^$B$12)/(((1+$B$11)^$B$12)-1) -> 647.15869 | E6: 6000 | F6: 1140 | G6: 13.2 | H6: 9.8 | I6: 3.3 | J6: 0.15 | K6: 430 | L6: =($B$18/K6)*((G6*I6)+(H6*J6)) -> 1497.5093 | M6: 1000 | N6: 600 | O6: 0 | P6: 15 | Q6: 11900 | R6: ='NPV-PHEV'!N4 -> -44436.33
A7: BEV | B7: 2024 Tesla Model 3 RWD | C7: 39000 | D7: =(C7-O7)*(($B$11)*(1+$B$11)^$B$12)/(((1+$B$11)^$B$12)-1) -> 532.95421 | E7: 15000 | F7: 3000 | G7: 0 | H7: 60 | I7: 0 | J7: 0.15 | K7: 310 | L7: =($B$18/K7)*((G7*I7)+(H7*J7)) -> 415.16129 | M7: 500 | N7: 400 | O7: =B20+B21 -> 11000 | P7: 15 | Q7: 13650 | R7: ='NPV-BEV'!N4 -> -32002.201
A10: Auto Loan Interest | B10: 0.11
A11: Monthly Rate | B11: =B10/12 -> 0.0091666667
A12: Loan Term [months] | B12: 72
A14: Commute [mi/day] | B14: 50
A15: Weekdays Commuted/yr | B15: 250
A16: Weekend Travel [mi] | B16: 100
A17: Weekends Traveled/yr | B17: 18
A18: Annual Miles [mi/yr] | B18: =(B14)*B15+B16*B17 -> 14300
A20: DoE EV Tax Credit | B20: 7500
A21: Colorado EV Tax Credit | B21: 3500
A23: Average MSRPs | B23: =average(C3:C7) -> 31000
A24: Std Dev of MSRPs | B24: =_xlfn.STDEV.S(C3:C7) -> 6403.1242
A25: 1st Quartile (25%) | B25: =QUARTILE(C3:C7,1) -> 28000
A26: 3rd Quartile (75%) | B26: =QUARTILE(C3:C7,3) -> 34000
A28: Colorado Registration Fees | B28: See Table for Calc Method _>
A30: Discount Rate | B30: 0.06

Sheet NPV-Gas
C1: Calculations
E2: 2024 Toyota Corolla LE (GAS)
C3: Year | D3: Month | E3: Loan | F3: Home Charger Install | G3: Fuel Cost | H3: Registration? | I3: Maintenance | J3: New Battery | K3: Salvage | L3: Sum | M3: PV | N3: NPV
A4: Discount Rate? | B4: =Calculations!$B$30 -> 0.06 | C4: 0 | D4: 0 | F4: =-Calculations!F3 -> 0 | L4: =SUM(E4:K4) -> 0 | M4: =L4/(1+$B$4/12)^D4 -> 0 | N4: =sum(M4:M76) -> -30770.265
C5: 1 | D5: 1 | E5: =-Calculations!$D$3 -> -418.74974 | G5: =-Calculations!$L$3/12 -> -115.35333 | H5: =sum(B6:B7) -> -454.07 | L5: =SUM(E5:K5) -> -988.17307 | M5: =L5/(1+$B$4/12)^D5 -> -983.25679
A6: Registration Fees | B6: =-18-23-9-4-0.94-1.5-0.7-2-0.5-1-0.33-0.3-0.1 -> -61.37 | C6: 1 | D6: 2 | E6: =-Calculations!$D$3 -> -418.74974 | G6: =-Calculations!$L$3/12 -> -115.35333 | L6: =SUM(E6:K6) -> -534.10307 | M6: =L6/(1+$B$4/12)^D6 -> -528.80183
A7: SOT Year 1 | B7: =-Calculations!$C$3*0.85*0.021 -> -392.7 | C7: 1 | D7: 3 | E7: =-Calculations!$D$3 -> -418.74974 | G7: =-Calculations!$L$3/12 -> -115.35333 | L7: =SUM(E7:K7) -> -534.10307 | M7: =L7/(1+$B$4/12)^D7 -> -526.17098
A8: SOT Year 2 | B8: =-Calculations!$C$3*0.85*0.015 -> -280.5 | C8: 1 | D8: 4 | E8: =-Calculations!$D$3 -> -418.74974 | G8: =-Calculations!$L$3/12 -> -115.35333 | L8: =SUM(E8:K8) -> -534.10307 | M8: =L8/(1+$B$4/12)^D8 -> -523.55321
A9: SOT Year 3 | B9: =-Calculations!$C$3*0.85*0.012 -> -224.4 | C9: 1 | D9: 5 | E9: =-Calculations!$D$3 -> -418.74974 | G9: =-Calculations!$L$3/12 -> -115.35333 | L9: =SUM(E9:K9) -> -534.10307 | M9: =L9/(1+$B$4/12)^D9 -> -520.94847
A10: SOT Year 4 | B10: =-Calculations!$C$3*0.85*0.009 -> -168.3 | C10: 1 | D10: 6 | E10: =-Calculations!$D$3 -> -418.74974 | G10: =-Calculations!$L$3/12 -> -115.35333 | I10: =-Calculations!$N$3/2 -> -250 | L10: =SUM(E10:K10) -> -784.10307 | M10: =L10/(1+$B$4/12)^D10 -> -760.98621
A11: SOT Year 5 | B11: =-Calculations!$C$3*0.85*0.0045 -> -84.15 | C11: 1 | D11: 7 | E11: =-Calculations!$D$3 -> -418.74974 | G11: =-Calculations!$L$3/12 -> -115.35333 | L11: =SUM(E11:K11) -> -534.10307 | M11: =L11/(1+$B$4/12)^D11 -> -515.7778
A12: SOT Year 6 | B12: =-Calculations!$C$3*0.85*0.0045 -> -84.15 | C12: 1 | D12: 8 | E12: =-Calculations!$D$3 -> -418.74974 | G12: =-Calculations!$L$3/12 -> -115.35333 | L12: =SUM(E12:K12) -> -534.10307 | M12: =L12/(1+$B$4/12)^D12 -> -513.21174
C13: 1 | D13: 9 | E13: =-Calculations!$D$3 -> -418.74974 | G13: =-Calculations!$L$3/12 -> -115.35333 | L13: =SUM(E13:K13) -> -534.10307 | M13: =L13/(1+$B$4/12)^D13 -> -510.65845
C14: 1 | D14: 10 | E14: =-Calculations!$D$3 -> -418.74974 | G14: =-Calculations!$L$3/12 -> -115.35333 | L14: =SUM(E14:K14) -> -534.10307 | M14: =L14/(1+$B$4/12)^D14 -> -508.11786
C15: 1 | D15: 11 | E15: =-Calculations!$D$3 -> -418.74974 | G15: =-Calculations!$L$3/12 -> -115.35333 | L15: =SUM(E15:K15) -> -534.10307 | M15: =L15/(1+$B$4/12)^D15 -> -505.58991
C16: 1 | D16: 12 | E16: =-Calculations!$D$3 -> -418.74974 | G16: =-Calculations!$L$3/12 -> -115.35333 | I16: =-Calculations!$N$3/2 -> -250 | L16: =SUM(E16:K16) -> -784.10307 | M16: =L16/(1+$B$4/12)^D16 -> -738.55087
C17: 2 | D17: 13 | E17: =-Calculations!$D$3 -> -418.74974 | G17: =-Calculations!$L$3/12 -> -115.35333 | H17: =sum(B6,B8) -> -341.87 | L17: =SUM(E17:K17) -> -875.97307 | M17: =L17/(1+$B$4/12)^D17 -> -820.97882
C18: 2 | D18: 14 | E18: =-Calculations!$D$3 -> -418.74974 | G18: =-Calculations!$L$3/12 -> -115.35333 | L18: =SUM(E18:K18) -> -534.10307 | M18: =L18/(1+$B$4/12)^D18 -> -498.08127
C19: 2 | D19: 15 | E19: =-Calculations!$D$3 -> -418.74974 | G19: =-Calculations!$L$3/12 -> -115.35333 | L19: =SUM(E19:K19) -> -534.10307 | M19: =L19/(1+$B$4/12)^D19 -> -495.60325
C20: 2 | D20: 16 | E20: =-Calculations!$D$3 -> -418.74974 | G20: =-Calculations!$L$3/12 -> -115.35333 | L20: =SUM(E20:K20) -> -534.10307 | M20: =L20/(1+$B$4/12)^D20 -> -493.13757
C21: 2 | D21: 17 | E21: =-Calculations!$D$3 -> -418.74974 | G21: =-Calculations!$L$3/12 -> -115.35333 | L21: =SUM(E21:K21) -> -534.10307 | M21: =L21/(1+$B$4/12)^D21 -> -490.68415
C22: 2 | D22: 18 | E22: =-Calculations!$D$3 -> -418.74974 | G22: =-Calculations!$L$3/12 -> -115.35333 | I22: =-Calculations!$N$3/2 -> -250 | L22: =SUM(E22:K22) -> -784.10307 | M22: =L22/(1+$B$4/12)^D22 -> -716.77697
C23: 2 | D23: 19 | E23: =-Calculations!$D$3 -> -418.74974 | G23: =-Calculations!$L$3/12 -> -115.35333 | L23: =SUM(E23:K23) -> -534.10307 | M23: =L23/(1+$B$4/12)^D23 -> -485.81386
C24: 2 | D24: 20 | E24: =-Calculations!$D$3 -> -418.74974 | G24: =-Calculations!$L$3/12 -> -115.35333 | L24: =SUM(E24:K24) -> -534.10307 | M24: =L24/(1+$B$4/12)^D24 -> -483.39688
C25: 2 | D25: 21 | E25: =-Calculations!$D$3 -> -418.74974 | G25: =-Calculations!$L$3/12 -> -115.35333 | L25: =SUM(E25:K25) -> -534.10307 | M25: =L25/(1+$B$4/12)^D25 -> -480.99192
C26: 2 | D26: 22 | E26: =-Calculations!$D$3 -> -418.74974 | G26: =-Calculations!$L$3/12 -> -115.35333 | L26: =SUM(E26:K26) -> -534.10307 | M26: =L26/(1+$B$4/12)^D26 -> -478.59892
C27: 2 | D27: 23 | E27: =-Calculations!$D$3 -> -418.74974 | G27: =-Calculations!$L$3/12 -> -115.35333 | L27: =SUM(E27:K27) -> -534.10307 | M27: =L27/(1+$B$4/12)^D27 -> -476.21783
C28: 2 | D28: 24 | E28: =-Calculations!$D$3 -> -418.74974 | G28: =-Calculations!$L$3/12 -> -115.35333 | I28: =-Calculations!$N$3/2 -> -250 | L28: =SUM(E28:K28) -> -784.10307 | M28: =L28/(1+$B$4/12)^D28 -> -695.64501
C29: 3 | D29: 25 | E29: =-Calculations!$D$3 -> -418.74974 | G29: =-Calculations!$L$3/12 -> -115.35333 | H29: =sum(B9,B6) -> -285.77 | L29: =SUM(E29:K29) -> -819.87307 | M29: =L29/(1+$B$4/12)^D29 -> -723.76084
C30: 3 | D30: 26 | E30: =-Calculations!$D$3 -> -418.74974 | G30: =-Calculations!$L$3/12 -> -115.35333 | L30: =SUM(E30:K30) -> -534.10307 | M30: =L30/(1+$B$4/12)^D30 -> -469.14541
C31: 3 | D31: 27 | E31: =-Calculations!$D$3 -> -418.74974 | G31: =-Calculations!$L$3/12 -> -115.35333 | L31: =SUM(E31:K31) -> -534.10307 | M31: =L31/(1+$B$4/12)^D31 -> -466.81135
C32: 3 | D32: 28 | E32: =-Calculations!$D$3 -> -418.74974 | G32: =-Calculations!$L$3/12 -> -115.35333 | L32: =SUM(E32:K32) -> -534.10307 | M32: =L32/(1+$B$4/12)^D32 -> -464.48891
C33: 3 | D33: 29 | E33: =-Calculations!$D$3 -> -418.74974 | G33: =-Calculations!$L$3/12 -> -115.35333 | L33: =SUM(E33:K33) -> -534.10307 | M33: =L33/(1+$B$4/12)^D33 -> -462.17802
C34: 3 | D34: 30 | E34: =-Calculations!$D$3 -> -418.74974 | G34: =-Calculations!$L$3/12 -> -115.35333 | I34: =-Calculations!$N$3/2 -> -250 | L34: =SUM(E34:K34) -> -784.10307 | M34: =L34/(1+$B$4/12)^D34 -> -675.13606
C35: 3 | D35: 31 | E35: =-Calculations!$D$3 -> -418.74974 | G35: =-Calculations!$L$3/12 -> -115.35333 | L35: =SUM(E35:K35) -> -534.10307 | M35: =L35/(1+$B$4/12)^D35 -> -457.59067
C36: 3 | D36: 32 | E36: =-Calculations!$D$3 -> -418.74974 | G36: =-Calculations!$L$3/12 -> -115.35333 | L36: =SUM(E36:K36) -> -534.10307 | M36: =L36/(1+$B$4/12)^D36 -> -455.3141
C37: 3 | D37: 33 | E37: =-Calculations!$D$3 -> -418.74974 | G37: =-Calculations!$L$3/12 -> -115.35333 | L37: =SUM(E37:K37) -> -534.10307 | M37: =L37/(1+$B$4/12)^D37 -> -453.04886
C38: 3 | D38: 34 | E38: =-Calculations!$D$3 -> -418.74974 | G38: =-Calculations!$L$3/12 -> -115.35333 | L38: =SUM(E38:K38) -> -534.10307 | M38: =L38/(1+$B$4/12)^D38 -> -450.79488
C39: 3 | D39: 35 | E39: =-Calculations!$D$3 -> -418.74974 | G39: =-Calculations!$L$3/12 -> -115.35333 | L39: =SUM(E39:K39) -> -534.10307 | M39: =L39/(1+$B$4/12)^D39 -> -448.55212
C40: 3 | D40: 36 | E40: =-Calculations!$D$3 -> -418.74974 | G40: =-Calculations!$L$3/12 -> -115.35333 | I40: =-Calculations!$N$3/2 -> -250 | L40: =SUM(E40:K40) -> -784.10307 | M40: =L40/(1+$B$4/12)^D40 -> -655.23175
...

Sheet NPV-E85
C1: Calculations
E2: 2024 Chevy Malibu (E85)
C3: Year | D3: Month | E3: Loan | F3: Home Charger Install | G3: Fuel Cost | H3: Registration? | I3: Maintenance | J3: New Battery | K3: Salvage | L3: Sum | M3: PV | N3: NPV
A4: Discount Rate? | B4: =Calculations!$B$30 -> 0.06 | C4: 0 | D4: 0 | F4: =-Calculations!F4 -> 0 | L4: =SUM(E4:K4) -> 0 | M4: =L4/(1+$B$4/12)^D4 -> 0 | N4: =sum(M4:M76) -> -34952.215
C5: 1 | D5: 1 | E5: =-Calculations!$D$4 -> -532.95421 | G5: =-Calculations!$L$4/12 -> -85.583333 | H5: =sum(B6:B7) -> -561.17 | L5: =SUM(E5:K5) -> -1179.7075 | M5: =L5/(1+$B$4/12)^D5 -> -1173.8384
A6: Registration Fees | B6: =-18-23-9-4-0.94-1.5-0.7-2-0.5-1-0.33-0.3-0.1 -> -61.37 | C6: 1 | D6: 2 | E6: =-Calculations!$D$4 -> -532.95421 | G6: =-Calculations!$L$4/12 -> -85.583333 | L6: =SUM(E6:K6) -> -618.53755 | M6: =L6/(1+$B$4/12)^D6 -> -612.39825
A7: SOT Year 1 | B7: =-Calculations!$C$4*0.85*0.021 -> -499.8 | C7: 1 | D7: 3 | E7: =-Calculations!$D$4 -> -532.95421 | G7: =-Calculations!$L$4/12 -> -85.583333 | L7: =SUM(E7:K7) -> -618.53755 | M7: =L7/(1+$B$4/12)^D7 -> -609.3515
A8: SOT Year 2 | B8: =-Calculations!$C$4*0.85*0.015 -> -357 | C8: 1 | D8: 4 | E8: =-Calculations!$D$4 -> -532.95421 | G8: =-Calculations!$L$4/12 -> -85.583333 | L8: =SUM(E8:K8) -> -618.53755 | M8: =L8/(1+$B$4/12)^D8 -> -606.3199
A9: SOT Year 3 | B9: =-Calculations!$C$4*0.85*0.012 -> -285.6 | C9: 1 | D9: 5 | E9: =-Calculations!$D$4 -> -532.95421 | G9: =-Calculations!$L$4/12 -> -85.583333 | L9: =SUM(E9:K9) -> -618.53755 | M9: =L9/(1+$B$4/12)^D9 -> -603.30338
A10: SOT Year 4 | B10: =-Calculations!$C$4*0.85*0.009 -> -214.2 | C10: 1 | D10: 6 | E10: =-Calculations!$D$4 -> -532.95421 | G10: =-Calculations!$L$4/12 -> -85.583333 | I10: =-Calculations!$N$4/2 -> -275 | L10: =SUM(E10:K10) -> -893.53755 | M10: =L10/(1+$B$4/12)^D10 -> -867.19434
A11: SOT Year 5 | B11: =-Calculations!$C$4*0.85*0.0045 -> -107.1 | C11: 1 | D11: 7 | E11: =-Calculations!$D$4 -> -532.95421 | G11: =-Calculations!$L$4/12 -> -85.583333 | L11: =SUM(E11:K11) -> -618.53755 | M11: =L11/(1+$B$4/12)^D11 -> -597.31529
A12: SOT Year 6 | B12: =-Calculations!$C$4*0.85*0.0045 -> -107.1 | C12: 1 | D12: 8 | E12: =-Calculations!$D$4 -> -532.95421 | G12: =-Calculations!$L$4/12 -> -85.583333 | L12: =SUM(E12:K12) -> -618.53755 | M12: =L12/(1+$B$4/12)^D12 -> -594.34358
C13: 1 | D13: 9 | E13: =-Calculations!$D$4 -> -532.95421 | G13: =-Calculations!$L$4/12 -> -85.583333 | L13: =SUM(E13:K13) -> -618.53755 | M13: =L13/(1+$B$4/12)^D13 -> -591.38664
C14: 1 | D14: 10 | E14: =-Calculations!$D$4 -> -532.95421 | G14: =-Calculations!$L$4/12 -> -85.583333 | L14: =SUM(E14:K14) -> -618.53755 | M14: =L14/(1+$B$4/12)^D14 -> -588.44442
C15: 1 | D15: 11 | E15: =-Calculations!$D$4 -> -532.95421 | G15: =-Calculations!$L$4/12 -> -85.583333 | L15: =SUM(E15:K15) -> -618.53755 | M15: =L15/(1+$B$4/12)^D15 -> -585.51684
C16: 1 | D16: 12 | E16: =-Calculations!$D$4 -> -532.95421 | G16: =-Calculations!$L$4/12 -> -85.583333 | I16: =-Calculations!$N$4/2 -> -275 | L16: =SUM(E16:K16) -> -893.53755 | M16: =L16/(1+$B$4/12)^D16 -> -841.62779
C17: 2 | D17: 13 | E17: =-Calculations!$D$4 -> -532.95421 | G17: =-Calculations!$L$4/12 -> -85.583333 | H17: =sum(B6,B8) -> -418.37 | L17: =SUM(E17:K17) -> -1036.9075 | M17: =L17/(1+$B$4/12)^D17 -> -971.80971
C18: 2 | D18: 14 | E18: =-Calculations!$D$4 -> -532.95421 | G18: =-Calculations!$L$4/12 -> -85.583333 | L18: =SUM(E18:K18) -> -618.53755 | M18: =L18/(1+$B$4/12)^D18 -> -576.82118
C19: 2 | D19: 15 | E19: =-Calculations!$D$4 -> -532.95421 | G19: =-Calculations!$L$4/12 -> -85.583333 | L19: =SUM(E19:K19) -> -618.53755 | M19: =L19/(1+$B$4/12)^D19 -> -573.95143
C20: 2 | D20: 16 | E20: =-Calculations!$D$4 -> -532.95421 | G20: =-Calculations!$L$4/12 -> -85.583333 | L20: =SUM(E20:K20) -> -618.53755 | M20: =L20/(1+$B$4/12)^D20 -> -571.09595
C21: 2 | D21: 17 | E21: =-Calculations!$D$4 -> -532.95421 | G21: =-Calculations!$L$4/12 -> -85.583333 | L21: =SUM(E21:K21) -> -618.53755 | M21: =L21/(1+$B$4/12)^D21 -> -568.25467
C22: 2 | D22: 18 | E22: =-Calculations!$D$4 -> -532.95421 | G22: =-Calculations!$L$4/12 -> -85.583333 | I22: =-Calculations!$N$4/2 -> -275 | L22: =SUM(E22:K22) -> -893.53755 | M22: =L22/(1+$B$4/12)^D22 -> -816.81498
C23: 2 | D23: 19 | E23: =-Calculations!$D$4 -> -532.95421 | G23: =-Calculations!$L$4/12 -> -85.583333 | L23: =SUM(E23:K23) -> -618.53755 | M23: =L23/(1+$B$4/12)^D23 -> -562.61446
C24: 2 | D24: 20 | E24: =-Calculations!$D$4 -> -532.95421 | G24: =-Calculations!$L$4/12 -> -85.583333 | L24: =SUM(E24:K24) -> -618.53755 | M24: =L24/(1+$B$4/12)^D24 -> -559.81539
C25: 2 | D25: 21 | E25: =-Calculations!$D$4 -> -532.95421 | G25: =-Calculations!$L$4/12 -> -85.583333 | L25: =SUM(E25:K25) -> -618.53755 | M25: =L25/(1+$B$4/12)^D25 -> -557.03024
C26: 2 | D26: 22 | E26: =-Calculations!$D$4 -> -532.95421 | G26: =-Calculations!$L$4/12 -> -85.583333 | L26: =SUM(E26:K26) -> -618.53755 | M26: =L26/(1+$B$4/12)^D26 -> -554.25894
C27: 2 | D27: 23 | E27: =-Calculations!$D$4 -> -532.95421 | G27: =-Calculations!$L$4/12 -> -85.583333 | L27: =SUM(E27:K27) -> -618.53755 | M27: =L27/(1+$B$4/12)^D27 -> -551.50143
C28: 2 | D28: 24 | E28: =-Calculations!$D$4 -> -532.95421 | G28: =-Calculations!$L$4/12 -> -85.583333 | I28: =-Calculations!$N$4/2 -> -275 | L28: =SUM(E28:K28) -> -893.53755 | M28: =L28/(1+$B$4/12)^D28 -> -792.7337
C29: 3 | D29: 25 | E29: =-Calculations!$D$4 -> -532.95421 | G29: =-Calculations!$L$4/12 -> -85.583333 | H29: =sum(B9,B6) -> -346.97 | L29: =SUM(E29:K29) -> -965.50755 | M29: =L29/(1+$B$4/12)^D29 -> -852.32284
C30: 3 | D30: 26 | E30: =-Calculations!$D$4 -> -532.95421 | G30: =-Calculations!$L$4/12 -> -85.583333 | L30: =SUM(E30:K30) -> -618.53755 | M30: =L30/(1+$B$4/12)^D30 -> -543.31095
C31: 3 | D31: 27 | E31: =-Calculations!$D$4 -> -532.95421 | G31: =-Calculations!$L$4/12 -> -85.583333 | L31: =SUM(E31:K31) -> -618.53755 | M31: =L31/(1+$B$4/12)^D31 -> -540.60791
C32: 3 | D32: 28 | E32: =-Calculations!$D$4 -> -532.95421 | G32: =-Calculations!$L$4/12 -> -85.583333 | L32: =SUM(E32:K32) -> -618.53755 | M32: =L32/(1+$B$4/12)^D32 -> -537.91832
C33: 3 | D33: 29 | E33: =-Calculations!$D$4 -> -532.95421 | G33: =-Calculations!$L$4/12 -> -85.583333 | L33: =SUM(E33:K33) -> -618.53755 | M33: =L33/(1+$B$4/12)^D33 -> -535.24211
C34: 3 | D34: 30 | E34: =-Calculations!$D$4 -> -532.95421 | G34: =-Calculations!$L$4/12 -> -85.583333 | I34: =-Calculations!$N$4/2 -> -275 | L34: =SUM(E34:K34) -> -893.53755 | M34: =L34/(1+$B$4/12)^D34 -> -769.36239
C35: 3 | D35: 31 | E35: =-Calculations!$D$4 -> -532.95421 | G35: =-Calculations!$L$4/12 -> -85.583333 | L35: =SUM(E35:K35) -> -618.53755 | M35: =L35/(1+$B$4/12)^D35 -> -529.92957
C36: 3 | D36: 32 | E36: =-Calculations!$D$4 -> -532.95421 | G36: =-Calculations!$L$4/12 -> -85.583333 | L36: =SUM(E36:K36) -> -618.53755 | M36: =L36/(1+$B$4/12)^D36 -> -527.2931
C37: 3 | D37: 33 | E37: =-Calculations!$D$4 -> -532.95421 | G37: =-Calculations!$L$4/12 -> -85.583333 | L37: =SUM(E37:K37) -> -618.53755 | M37: =L37/(1+$B$4/12)^D37 -> -524.66975
C38: 3 | D38: 34 | E38: =-Calculations!$D$4 -> -532.95421 | G38: =-Calculations!$L$4/12 -> -85.583333 | L38: =SUM(E38:K38) -> -618.53755 | M38: =L38/(1+$B$4/12)^D38 -> -522.05946
C39: 3 | D39: 35 | E39: =-Calculations!$D$4 -> -532.95421 | G39: =-Calculations!$L$4/12 -> -85.583333 | L39: =SUM(E39:K39) -> -618.53755 | M39: =L39/(1+$B$4/12)^D39 -> -519.46215
C40: 3 | D40: 36 | E40: =-Calculations!$D$4 -> -532.95421 | G40: =-Calculations!$L$4/12 -> -85.583333 | I40: =-Calculations!$N$4/2 -> -275 | L40: =SUM(E40:K40) -> -893.53755 | M40: =L40/(1+$B$4/12)^D40 -> -746.68011
...

Sheet NPV-HEV
C1: Calculations
E2: 2024 Honda Accord Hybrid Sport (HEV)
C3: Year | D3: Month | E3: Loan | F3: Home Charger Install | G3: Fuel Cost | H3: Registration? | I3: Maintenance | J3: New Battery | K3: Salvage | L3: Sum | M3: PV | N3: NPV
A4: Discount Rate? | B4: =Calculations!$B$30 -> 0.06 | C4: 0 | D4: 0 | F4: =-Calculations!F5 -> -1200 | L4: =SUM(E4:K4) -> -1200 | M4: =L4/(1+$B$4/12)^D4 -> -1200 | N4: =sum(M4:M76) -> -40003.087
C5: 1 | D5: 1 | E5: =-Calculations!$D$5 -> -609.09053 | G5: =-Calculations!$L$5/12 -> -81.980456 | H5: =sum(B6:B7) -> -632.57 | L5: =SUM(E5:K5) -> -1323.641 | M5: =L5/(1+$B$4/12)^D5 -> -1317.0557
A6: Registration Fees | B6: =-18-23-9-4-0.94-1.5-0.7-2-0.5-1-0.33-0.3-0.1 -> -61.37 | C6: 1 | D6: 2 | E6: =-Calculations!$D$5 -> -609.09053 | G6: =-Calculations!$L$5/12 -> -81.980456 | L6: =SUM(E6:K6) -> -691.07098 | M6: =L6/(1+$B$4/12)^D6 -> -684.21176
A7: SOT Year 1 | B7: =-Calculations!$C$5*0.85*0.021 -> -571.2 | C7: 1 | D7: 3 | E7: =-Calculations!$D$5 -> -609.09053 | G7: =-Calculations!$L$5/12 -> -81.980456 | L7: =SUM(E7:K7) -> -691.07098 | M7: =L7/(1+$B$4/12)^D7 -> -680.80772
A8: SOT Year 2 | B8: =-Calculations!$C$5*0.85*0.015 -> -408 | C8: 1 | D8: 4 | E8: =-Calculations!$D$5 -> -609.09053 | G8: =-Calculations!$L$5/12 -> -81.980456 | L8: =SUM(E8:K8) -> -691.07098 | M8: =L8/(1+$B$4/12)^D8 -> -677.42062
A9: SOT Year 3 | B9: =-Calculations!$C$5*0.85*0.012 -> -326.4 | C9: 1 | D9: 5 | E9: =-Calculations!$D$5 -> -609.09053 | G9: =-Calculations!$L$5/12 -> -81.980456 | L9: =SUM(E9:K9) -> -691.07098 | M9: =L9/(1+$B$4/12)^D9 -> -674.05037
A10: SOT Year 4 | B10: =-Calculations!$C$5*0.85*0.009 -> -244.8 | C10: 1 | D10: 6 | E10: =-Calculations!$D$5 -> -609.09053 | G10: =-Calculations!$L$5/12 -> -81.980456 | I10: =-Calculations!$N$5/2 -> -300 | L10: =SUM(E10:K10) -> -991.07098 | M10: =L10/(1+$B$4/12)^D10 -> -961.85231
A11: SOT Year 5 | B11: =-Calculations!$C$5*0.85*0.0045 -> -122.4 | C11: 1 | D11: 7 | E11: =-Calculations!$D$5 -> -609.09053 | G11: =-Calculations!$L$5/12 -> -81.980456 | L11: =SUM(E11:K11) -> -691.07098 | M11: =L11/(1+$B$4/12)^D11 -> -667.36008
A12: SOT Year 6 | B12: =-Calculations!$C$5*0.85*0.0045 -> -122.4 | C12: 1 | D12: 8 | E12: =-Calculations!$D$5 -> -609.09053 | G12: =-Calculations!$L$5/12 -> -81.980456 | L12: =SUM(E12:K12) -> -691.07098 | M12: =L12/(1+$B$4/12)^D12 -> -664.03988
C13: 1 | D13: 9 | E13: =-Calculations!$D$5 -> -609.09053 | G13: =-Calculations!$L$5/12 -> -81.980456 | L13: =SUM(E13:K13) -> -691.07098 | M13: =L13/(1+$B$4/12)^D13 -> -660.7362
C14: 1 | D14: 10 | E14: =-Calculations!$D$5 -> -609.09053 | G14: =-Calculations!$L$5/12 -> -81.980456 | L14: =SUM(E14:K14) -> -691.07098 | M14: =L14/(1+$B$4/12)^D14 -> -657.44896
C15: 1 | D15: 11 | E15: =-Calculations!$D$5 -> -609.09053 | G15: =-Calculations!$L$5/12 -> -81.980456 | L15: =SUM(E15:K15) -> -691.07098 | M15: =L15/(1+$B$4/12)^D15 -> -654.17807
C16: 1 | D16: 12 | E16: =-Calculations!$D$5 -> -609.09053 | G16: =-Calculations!$L$5/12 -> -81.980456 | I16: =-Calculations!$N$5/2 -> -300 | L16: =SUM(E16:K16) -> -991.07098 | M16: =L16/(1+$B$4/12)^D16 -> -933.49505
C17: 2 | D17: 13 | E17: =-Calculations!$D$5 -> -609.09053 | G17: =-Calculations!$L$5/12 -> -81.980456 | H17: =sum(B6,B8) -> -469.37 | L17: =SUM(E17:K17) -> -1160.441 | M17: =L17/(1+$B$4/12)^D17 -> -1087.5876
C18: 2 | D18: 14 | E18: =-Calculations!$D$5 -> -609.09053 | G18: =-Calculations!$L$5/12 -> -81.980456 | L18: =SUM(E18:K18) -> -691.07098 | M18: =L18/(1+$B$4/12)^D18 -> -644.46271
C19: 2 | D19: 15 | E19: =-Calculations!$D$5 -> -609.09053 | G19: =-Calculations!$L$5/12 -> -81.980456 | L19: =SUM(E19:K19) -> -691.07098 | M19: =L19/(1+$B$4/12)^D19 -> -641.25643
C20: 2 | D20: 16 | E20: =-Calculations!$D$5 -> -609.09053 | G20: =-Calculations!$L$5/12 -> -81.980456 | L20: =SUM(E20:K20) -> -691.07098 | M20: =L20/(1+$B$4/12)^D20 -> -638.0661
C21: 2 | D21: 17 | E21: =-Calculations!$D$5 -> -609.09053 | G21: =-Calculations!$L$5/12 -> -81.980456 | L21: =SUM(E21:K21) -> -691.07098 | M21: =L21/(1+$B$4/12)^D21 -> -634.89164
C22: 2 | D22: 18 | E22: =-Calculations!$D$5 -> -609.09053 | G22: =-Calculations!$L$5/12 -> -81.980456 | I22: =-Calculations!$N$5/2 -> -300 | L22: =SUM(E22:K22) -> -991.07098 | M22: =L22/(1+$B$4/12)^D22 -> -905.97382
C23: 2 | D23: 19 | E23: =-Calculations!$D$5 -> -609.09053 | G23: =-Calculations!$L$5/12 -> -81.980456 | L23: =SUM(E23:K23) -> -691.07098 | M23: =L23/(1+$B$4/12)^D23 -> -628.59003
C24: 2 | D24: 20 | E24: =-Calculations!$D$5 -> -609.09053 | G24: =-Calculations!$L$5/12 -> -81.980456 | L24: =SUM(E24:K24) -> -691.07098 | M24: =L24/(1+$B$4/12)^D24 -> -625.46271
C25: 2 | D25: 21 | E25: =-Calculations!$D$5 -> -609.09053 | G25: =-Calculations!$L$5/12 -> -81.980456 | L25: =SUM(E25:K25) -> -691.07098 | M25: =L25/(1+$B$4/12)^D25 -> -622.35096
C26: 2 | D26: 22 | E26: =-Calculations!$D$5 -> -609.09053 | G26: =-Calculations!$L$5/12 -> -81.980456 | L26: =SUM(E26:K26) -> -691.07098 | M26: =L26/(1+$B$4/12)^D26 -> -619.25468
C27: 2 | D27: 23 | E27: =-Calculations!$D$5 -> -609.09053 | G27: =-Calculations!$L$5/12 -> -81.980456 | L27: =SUM(E27:K27) -> -691.07098 | M27: =L27/(1+$B$4/12)^D27 -> -616.17381
C28: 2 | D28: 24 | E28: =-Calculations!$D$5 -> -609.09053 | G28: =-Calculations!$L$5/12 -> -81.980456 | I28: =-Calculations!$N$5/2 -> -300 | L28: =SUM(E28:K28) -> -991.07098 | M28: =L28/(1+$B$4/12)^D28 -> -879.26397
C29: 3 | D29: 25 | E29: =-Calculations!$D$5 -> -609.09053 | G29: =-Calculations!$L$5/12 -> -81.980456 | H29: =sum(B9,B6) -> -387.77 | L29: =SUM(E29:K29) -> -1078.841 | M29: =L29/(1+$B$4/12)^D29 -> -952.37041
C30: 3 | D30: 26 | E30: =-Calculations!$D$5 -> -609.09053 | G30: =-Calculations!$L$5/12 -> -81.980456 | L30: =SUM(E30:K30) -> -691.07098 | M30: =L30/(1+$B$4/12)^D30 -> -607.02287
C31: 3 | D31: 27 | E31: =-Calculations!$D$5 -> -609.09053 | G31: =-Calculations!$L$5/12 -> -81.980456 | L31: =SUM(E31:K31) -> -691.07098 | M31: =L31/(1+$B$4/12)^D31 -> -604.00285
C32: 3 | D32: 28 | E32: =-Calculations!$D$5 -> -609.09053 | G32: =-Calculations!$L$5/12 -> -81.980456 | L32: =SUM(E32:K32) -> -691.07098 | M32: =L32/(1+$B$4/12)^D32 -> -600.99787
C33: 3 | D33: 29 | E33: =-Calculations!$D$5 -> -609.09053 | G33: =-Calculations!$L$5/12 -> -81.980456 | L33: =SUM(E33:K33) -> -691.07098 | M33: =L33/(1+$B$4/12)^D33 -> -598.00783
C34: 3 | D34: 30 | E34: =-Calculations!$D$5 -> -609.09053 | G34: =-Calculations!$L$5/12 -> -81.980456 | I34: =-Calculations!$N$5/2 -> -300 | L34: =SUM(E34:K34) -> -991.07098 | M34: =L34/(1+$B$4/12)^D34 -> -853.34158
C35: 3 | D35: 31 | E35: =-Calculations!$D$5 -> -609.09053 | G35: =-Calculations!$L$5/12 -> -81.980456 | L35: =SUM(E35:K35) -> -691.07098 | M35: =L35/(1+$B$4/12)^D35 -> -592.0723
C36: 3 | D36: 32 | E36: =-Calculations!$D$5 -> -609.09053 | G36: =-Calculations!$L$5/12 -> -81.980456 | L36: =SUM(E36:K36) -> -691.07098 | M36: =L36/(1+$B$4/12)^D36 -> -589.12667
C37: 3 | D37: 33 | E37: =-Calculations!$D$5 -> -609.09053 | G37: =-Calculations!$L$5/12 -> -81.980456 | L37: =SUM(E37:K37) -> -691.07098 | M37: =L37/(1+$B$4/12)^D37 -> -586.19569
C38: 3 | D38: 34 | E38: =-Calculations!$D$5 -> -609.09053 | G38: =-Calculations!$L$5/12 -> -81.980456 | L38: =SUM(E38:K38) -> -691.07098 | M38: =L38/(1+$B$4/12)^D38 -> -583.27929
C39: 3 | D39: 35 | E39: =-Calculations!$D$5 -> -609.09053 | G39: =-Calculations!$L$5/12 -> -81.980456 | L39: =SUM(E39:K39) -> -691.07098 | M39: =L39/(1+$B$4/12)^D39 -> -580.37741
C40: 3 | D40: 36 | E40: =-Calculations!$D$5 -> -609.09053 | G40: =-Calculations!$L$5/12 -> -81.980456 | I40: =-Calculations!$N$5/2 -> -300 | L40: =SUM(E40:K40) -> -991.07098 | M40: =L40/(1+$B$4/12)^D40 -> -828.18343
...

Sheet NPV-PHEV
C1: Calculations
E2: 2024 Hyundai Sonata Plug-in Hybrid (PHEV)
C3: Year | D3: Month | E3: Loan | F3: Home Charger Install | G3: Fuel Cost | H3: Registration? | I3: Maintenance | J3: New Battery | K3: Salvage | L3: Sum | M3: PV | N3: NPV
A4: Discount Rate? | B4: =Calculations!$B$30 -> 0.06 | C4: 0 | D4: 0 | F4: =-Calculations!F6 -> -1140 | L4: =SUM(E4:K4) -> -1140 | M4: =L4/(1+$B$4/12)^D4 -> -1140 | N4: =sum(M4:M76) -> -44436.33
C5: 1 | D5: 1 | E5: =-Calculations!$D$6 -> -647.15869 | G5: =-Calculations!$L$6/12 -> -124.79244 | H5: =sum(B6:B7) -> -668.27 | L5: =SUM(E5:K5) -> -1440.2211 | M5: =L5/(1+$B$4/12)^D5 -> -1433.0558
A6: Registration Fees | B6: =-18-23-9-4-0.94-1.5-0.7-2-0.5-1-0.33-0.3-0.1 -> -61.37 | C6: 1 | D6: 2 | E6: =-Calculations!$D$6 -> -647.15869 | G6: =-Calculations!$L$6/12 -> -124.79244 | L6: =SUM(E6:K6) -> -771.95113 | M6: =L6/(1+$B$4/12)^D6 -> -764.28913
A7: SOT Year 1 | B7: =-Calculations!$C$6*0.85*0.021 -> -606.9 | C7: 1 | D7: 3 | E7: =-Calculations!$D$6 -> -647.15869 | G7: =-Calculations!$L$6/12 -> -124.79244 | L7: =SUM(E7:K7) -> -771.95113 | M7: =L7/(1+$B$4/12)^D7 -> -760.4867
A8: SOT Year 2 | B8: =-Calculations!$C$6*0.85*0.015 -> -433.5 | C8: 1 | D8: 4 | E8: =-Calculations!$D$6 -> -647.15869 | G8: =-Calculations!$L$6/12 -> -124.79244 | L8: =SUM(E8:K8) -> -771.95113 | M8: =L8/(1+$B$4/12)^D8 -> -756.70318
A9: SOT Year 3 | B9: =-Calculations!$C$6*0.85*0.012 -> -346.8 | C9: 1 | D9: 5 | E9: =-Calculations!$D$6 -> -647.15869 | G9: =-Calculations!$L$6/12 -> -124.79244 | L9: =SUM(E9:K9) -> -771.95113 | M9: =L9/(1+$B$4/12)^D9 -> -752.93849
A10: SOT Year 4 | B10: =-Calculations!$C$6*0.85*0.009 -> -260.1 | C10: 1 | D10: 6 | E10: =-Calculations!$D$6 -> -647.15869 | G10: =-Calculations!$L$6/12 -> -124.79244 | I10: =-Calculations!$N$6/2 -> -300 | L10: =SUM(E10:K10) -> -1071.9511 | M10: =L10/(1+$B$4/12)^D10 -> -1040.3479
A11: SOT Year 5 | B11: =-Calculations!$C$6*0.85*0.0045 -> -130.05 | C11: 1 | D11: 7 | E11: =-Calculations!$D$6 -> -647.15869 | G11: =-Calculations!$L$6/12 -> -124.79244 | L11: =SUM(E11:K11) -> -771.95113 | M11: =L11/(1+$B$4/12)^D11 -> -745.4652
A12: SOT Year 6 | B12: =-Calculations!$C$6*0.85*0.0045 -> -130.05 | C12: 1 | D12: 8 | E12: =-Calculations!$D$6 -> -647.15869 | G12: =-Calculations!$L$6/12 -> -124.79244 | L12: =SUM(E12:K12) -> -771.95113 | M12: =L12/(1+$B$4/12)^D12 -> -741.75642
C13: 1 | D13: 9 | E13: =-Calculations!$D$6 -> -647.15869 | G13: =-Calculations!$L$6/12 -> -124.79244 | L13: =SUM(E13:K13) -> -771.95113 | M13: =L13/(1+$B$4/12)^D13 -> -738.06609
C14: 1 | D14: 10 | E14: =-Calculations!$D$6 -> -647.15869 | G14: =-Calculations!$L$6/12 -> -124.79244 | L14: =SUM(E14:K14) -> -771.95113 | M14: =L14/(1+$B$4/12)^D14 -> -734.39412
C15: 1 | D15: 11 | E15: =-Calculations!$D$6 -> -647.15869 | G15: =-Calculations!$L$6/12 -> -124.79244 | L15: =SUM(E15:K15) -> -771.95113 | M15: =L15/(1+$B$4/12)^D15 -> -730.74041
C16: 1 | D16: 12 | E16: =-Calculations!$D$6 -> -647.15869 | G16: =-Calculations!$L$6/12 -> -124.79244 | I16: =-Calculations!$N$6/2 -> -300 | L16: =SUM(E16:K16) -> -1071.9511 | M16: =L16/(1+$B$4/12)^D16 -> -1009.6765
C17: 2 | D17: 13 | E17: =-Calculations!$D$6 -> -647.15869 | G17: =-Calculations!$L$6/12 -> -124.79244 | H17: =sum(B6,B8) -> -494.87 | L17: =SUM(E17:K17) -> -1266.8211 | M17: =L17/(1+$B$4/12)^D17 -> -1187.2891
C18: 2 | D18: 14 | E18: =-Calculations!$D$6 -> -647.15869 | G18: =-Calculations!$L$6/12 -> -124.79244 | L18: =SUM(E18:K18) -> -771.95113 | M18: =L18/(1+$B$4/12)^D18 -> -719.88801
C19: 2 | D19: 15 | E19: =-Calculations!$D$6 -> -647.15869 | G19: =-Calculations!$L$6/12 -> -124.79244 | L19: =SUM(E19:K19) -> -771.95113 | M19: =L19/(1+$B$4/12)^D19 -> -716.30648
C20: 2 | D20: 16 | E20: =-Calculations!$D$6 -> -647.15869 | G20: =-Calculations!$L$6/12 -> -124.79244 | L20: =SUM(E20:K20) -> -771.95113 | M20: =L20/(1+$B$4/12)^D20 -> -712.74277
C21: 2 | D21: 17 | E21: =-Calculations!$D$6 -> -647.15869 | G21: =-Calculations!$L$6/12 -> -124.79244 | L21: =SUM(E21:K21) -> -771.95113 | M21: =L21/(1+$B$4/12)^D21 -> -709.19678
C22: 2 | D22: 18 | E22: =-Calculations!$D$6 -> -647.15869 | G22: =-Calculations!$L$6/12 -> -124.79244 | I22: =-Calculations!$N$6/2 -> -300 | L22: =SUM(E22:K22) -> -1071.9511 | M22: =L22/(1+$B$4/12)^D22 -> -979.90929
C23: 2 | D23: 19 | E23: =-Calculations!$D$6 -> -647.15869 | G23: =-Calculations!$L$6/12 -> -124.79244 | L23: =SUM(E23:K23) -> -771.95113 | M23: =L23/(1+$B$4/12)^D23 -> -702.15765
C24: 2 | D24: 20 | E24: =-Calculations!$D$6 -> -647.15869 | G24: =-Calculations!$L$6/12 -> -124.79244 | L24: =SUM(E24:K24) -> -771.95113 | M24: =L24/(1+$B$4/12)^D24 -> -698.66433
C25: 2 | D25: 21 | E25: =-Calculations!$D$6 -> -647.15869 | G25: =-Calculations!$L$6/12 -> -124.79244 | L25: =SUM(E25:K25) -> -771.95113 | M25: =L25/(1+$B$4/12)^D25 -> -695.18839
C26: 2 | D26: 22 | E26: =-Calculations!$D$6 -> -647.15869 | G26: =-Calculations!$L$6/12 -> -124.79244 | L26: =SUM(E26:K26) -> -771.95113 | M26: =L26/(1+$B$4/12)^D26 -> -691.72974
C27: 2 | D27: 23 | E27: =-Calculations!$D$6 -> -647.15869 | G27: =-Calculations!$L$6/12 -> -124.79244 | L27: =SUM(E27:K27) -> -771.95113 | M27: =L27/(1+$B$4/12)^D27 -> -688.2883
C28: 2 | D28: 24 | E28: =-Calculations!$D$6 -> -647.15869 | G28: =-Calculations!$L$6/12 -> -124.79244 | I28: =-Calculations!$N$6/2 -> -300 | L28: =SUM(E28:K28) -> -1071.9511 | M28: =L28/(1+$B$4/12)^D28 -> -951.01968
C29: 3 | D29: 25 | E29: =-Calculations!$D$6 -> -647.15869 | G29: =-Calculations!$L$6/12 -> -124.79244 | H29: =sum(B9,B6) -> -408.17 | L29: =SUM(E29:K29) -> -1180.1211 | M29: =L29/(1+$B$4/12)^D29 -> -1041.7777
C30: 3 | D30: 26 | E30: =-Calculations!$D$6 -> -647.15869 | G30: =-Calculations!$L$6/12 -> -124.79244 | L30: =SUM(E30:K30) -> -771.95113 | M30: =L30/(1+$B$4/12)^D30 -> -678.06636
C31: 3 | D31: 27 | E31: =-Calculations!$D$6 -> -647.15869 | G31: =-Calculations!$L$6/12 -> -124.79244 | L31: =SUM(E31:K31) -> -771.95113 | M31: =L31/(1+$B$4/12)^D31 -> -674.6929
C32: 3 | D32: 28 | E32: =-Calculations!$D$6 -> -647.15869 | G32: =-Calculations!$L$6/12 -> -124.79244 | L32: =SUM(E32:K32) -> -771.95113 | M32: =L32/(1+$B$4/12)^D32 -> -671.33622
C33: 3 | D33: 29 | E33: =-Calculations!$D$6 -> -647.15869 | G33: =-Calculations!$L$6/12 -> -124.79244 | L33: =SUM(E33:K33) -> -771.95113 | M33: =L33/(1+$B$4/12)^D33 -> -667.99624
C34: 3 | D34: 30 | E34: =-Calculations!$D$6 -> -647.15869 | G34: =-Calculations!$L$6/12 -> -124.79244 | I34: =-Calculations!$N$6/2 -> -300 | L34: =SUM(E34:K34) -> -1071.9511 | M34: =L34/(1+$B$4/12)^D34 -> -922.98179
C35: 3 | D35: 31 | E35: =-Calculations!$D$6 -> -647.15869 | G35: =-Calculations!$L$6/12 -> -124.79244 | L35: =SUM(E35:K35) -> -771.95113 | M35: =L35/(1+$B$4/12)^D35 -> -661.36604
C36: 3 | D36: 32 | E36: =-Calculations!$D$6 -> -647.15869 | G36: =-Calculations!$L$6/12 -> -124.79244 | L36: =SUM(E36:K36) -> -771.95113 | M36: =L36/(1+$B$4/12)^D36 -> -658.07566
C37: 3 | D37: 33 | E37: =-Calculations!$D$6 -> -647.15869 | G37: =-Calculations!$L$6/12 -> -124.79244 | L37: =SUM(E37:K37) -> -771.95113 | M37: =L37/(1+$B$4/12)^D37 -> -654.80165
C38: 3 | D38: 34 | E38: =-Calculations!$D$6 -> -647.15869 | G38: =-Calculations!$L$6/12 -> -124.79244 | L38: =SUM(E38:K38) -> -771.95113 | M38: =L38/(1+$B$4/12)^D38 -> -651.54393
C39: 3 | D39: 35 | E39: =-Calculations!$D$6 -> -647.15869 | G39: =-Calculations!$L$6/12 -> -124.79244 | L39: =SUM(E39:K39) -> -771.95113 | M39: =L39/(1+$B$4/12)^D39 -> -648.30242
C40: 3 | D40: 36 | E40: =-Calculations!$D$6 -> -647.15869 | G40: =-Calculations!$L$6/12 -> -124.79244 | I40: =-Calculations!$N$6/2 -> -300 | L40: =SUM(E40:K40) -> -1071.9511 | M40: =L40/(1+$B$4/12)^D40 -> -895.77051
...

Sheet NPV-BEV
C1: Calculations
E2: 2024 Tesla Model 3 RWD (BEV)
C3: Year | D3: Month | E3: Loan | F3: Home Charger Install | G3: Fuel Cost | H3: Registration? | I3: Maintenance | J3: New Battery | K3: Salvage | L3: Sum | M3: PV | N3: NPV
A4: Discount Rate? | B4: =Calculations!$B$30 -> 0.06 | C4: 0 | D4: 0 | F4: =-Calculations!F7 -> -3000 | L4: =SUM(E4:K4) -> -3000 | M4: =L4/(1+$B$4/12)^D4 -> -3000 | N4: =sum(M4:M76) -> -32002.201
C5: 1 | D5: 1 | E5: =-Calculations!$D$7 -> -532.95421 | G5: =-Calculations!$L$7/12 -> -34.596774 | H5: =sum(B6:B7) -> -757.52 | L5: =SUM(E5:K5) -> -1325.071 | M5: =L5/(1+$B$4/12)^D5 -> -1318.4786
A6: Registration Fees | B6: =-18-23-9-4-0.94-1.5-0.7-2-0.5-1-0.33-0.3-0.1 -> -61.37 | C6: 1 | D6: 2 | E6: =-Calculations!$D$7 -> -532.95421 | G6: =-Calculations!$L$7/12 -> -34.596774 | L6: =SUM(E6:K6) -> -567.55099 | M6: =L6/(1+$B$4/12)^D6 -> -561.91776
A7: SOT Year 1 | B7: =-Calculations!$C$7*0.85*0.021 -> -696.15 | C7: 1 | D7: 3 | E7: =-Calculations!$D$7 -> -532.95421 | G7: =-Calculations!$L$7/12 -> -34.596774 | L7: =SUM(E7:K7) -> -567.55099 | M7: =L7/(1+$B$4/12)^D7 -> -559.12215
A8: SOT Year 2 | B8: =-Calculations!$C$7*0.85*0.015 -> -497.25 | C8: 1 | D8: 4 | E8: =-Calculations!$D$7 -> -532.95421 | G8: =-Calculations!$L$7/12 -> -34.596774 | L8: =SUM(E8:K8) -> -567.55099 | M8: =L8/(1+$B$4/12)^D8 -> -556.34045
A9: SOT Year 3 | B9: =-Calculations!$C$7*0.85*0.012 -> -397.8 | C9: 1 | D9: 5 | E9: =-Calculations!$D$7 -> -532.95421 | G9: =-Calculations!$L$7/12 -> -34.596774 | L9: =SUM(E9:K9) -> -567.55099 | M9: =L9/(1+$B$4/12)^D9 -> -553.57258
A10: SOT Year 4 | B10: =-Calculations!$C$7*0.85*0.009 -> -298.35 | C10: 1 | D10: 6 | E10: =-Calculations!$D$7 -> -532.95421 | G10: =-Calculations!$L$7/12 -> -34.596774 | I10: =-Calculations!$N$7/2 -> -200 | L10: =SUM(E10:K10) -> -767.55099 | M10: =L10/(1+$B$4/12)^D10 -> -744.92211
A11: SOT Year 5 | B11: =-Calculations!$C$7*0.85*0.0045 -> -149.175 | C11: 1 | D11: 7 | E11: =-Calculations!$D$7 -> -532.95421 | G11: =-Calculations!$L$7/12 -> -34.596774 | L11: =SUM(E11:K11) -> -567.55099 | M11: =L11/(1+$B$4/12)^D11 -> -548.0781
A12: SOT Year 6 | B12: =-Calculations!$C$7*0.85*0.0045 -> -149.175 | C12: 1 | D12: 8 | E12: =-Calculations!$D$7 -> -532.95421 | G12: =-Calculations!$L$7/12 -> -34.596774 | L12: =SUM(E12:K12) -> -567.55099 | M12: =L12/(1+$B$4/12)^D12 -> -545.35135
C13: 1 | D13: 9 | E13: =-Calculations!$D$7 -> -532.95421 | G13: =-Calculations!$L$7/12 -> -34.596774 | L13: =SUM(E13:K13) -> -567.55099 | M13: =L13/(1+$B$4/12)^D13 -> -542.63815
C14: 1 | D14: 10 | E14: =-Calculations!$D$7 -> -532.95421 | G14: =-Calculations!$L$7/12 -> -34.596774 | L14: =SUM(E14:K14) -> -567.55099 | M14: =L14/(1+$B$4/12)^D14 -> -539.93846
C15: 1 | D15: 11 | E15: =-Calculations!$D$7 -> -532.95421 | G15: =-Calculations!$L$7/12 -> -34.596774 | L15: =SUM(E15:K15) -> -567.55099 | M15: =L15/(1+$B$4/12)^D15 -> -537.2522
C16: 1 | D16: 12 | E16: =-Calculations!$D$7 -> -532.95421 | G16: =-Calculations!$L$7/12 -> -34.596774 | I16: =-Calculations!$N$7/2 -> -200 | L16: =SUM(E16:K16) -> -767.55099 | M16: =L16/(1+$B$4/12)^D16 -> -722.96037
C17: 2 | D17: 13 | E17: =-Calculations!$D$7 -> -532.95421 | G17: =-Calculations!$L$7/12 -> -34.596774 | H17: =sum(B6,B8) -> -558.62 | L17: =SUM(E17:K17) -> -1126.171 | M17: =L17/(1+$B$4/12)^D17 -> -1055.4691
C18: 2 | D18: 14 | E18: =-Calculations!$D$7 -> -532.95421 | G18: =-Calculations!$L$7/12 -> -34.596774 | L18: =SUM(E18:K18) -> -567.55099 | M18: =L18/(1+$B$4/12)^D18 -> -529.27334
C19: 2 | D19: 15 | E19: =-Calculations!$D$7 -> -532.95421 | G19: =-Calculations!$L$7/12 -> -34.596774 | L19: =SUM(E19:K19) -> -567.55099 | M19: =L19/(1+$B$4/12)^D19 -> -526.64014
C20: 2 | D20: 16 | E20: =-Calculations!$D$7 -> -532.95421 | G20: =-Calculations!$L$7/12 -> -34.596774 | L20: =SUM(E20:K20) -> -567.55099 | M20: =L20/(1+$B$4/12)^D20 -> -524.02004
C21: 2 | D21: 17 | E21: =-Calculations!$D$7 -> -532.95421 | G21: =-Calculations!$L$7/12 -> -34.596774 | L21: =SUM(E21:K21) -> -567.55099 | M21: =L21/(1+$B$4/12)^D21 -> -521.41297
C22: 2 | D22: 18 | E22: =-Calculations!$D$7 -> -532.95421 | G22: =-Calculations!$L$7/12 -> -34.596774 | I22: =-Calculations!$N$7/2 -> -200 | L22: =SUM(E22:K22) -> -767.55099 | M22: =L22/(1+$B$4/12)^D22 -> -701.64611
C23: 2 | D23: 19 | E23: =-Calculations!$D$7 -> -532.95421 | G23: =-Calculations!$L$7/12 -> -34.596774 | L23: =SUM(E23:K23) -> -567.55099 | M23: =L23/(1+$B$4/12)^D23 -> -516.23769
C24: 2 | D24: 20 | E24: =-Calculations!$D$7 -> -532.95421 | G24: =-Calculations!$L$7/12 -> -34.596774 | L24: =SUM(E24:K24) -> -567.55099 | M24: =L24/(1+$B$4/12)^D24 -> -513.66934
C25: 2 | D25: 21 | E25: =-Calculations!$D$7 -> -532.95421 | G25: =-Calculations!$L$7/12 -> -34.596774 | L25: =SUM(E25:K25) -> -567.55099 | M25: =L25/(1+$B$4/12)^D25 -> -511.11377
C26: 2 | D26: 22 | E26: =-Calculations!$D$7 -> -532.95421 | G26: =-Calculations!$L$7/12 -> -34.596774 | L26: =SUM(E26:K26) -> -567.55099 | M26: =L26/(1+$B$4/12)^D26 -> -508.57092
C27: 2 | D27: 23 | E27: =-Calculations!$D$7 -> -532.95421 | G27: =-Calculations!$L$7/12 -> -34.596774 | L27: =SUM(E27:K27) -> -567.55099 | M27: =L27/(1+$B$4/12)^D27 -> -506.04072
C28: 2 | D28: 24 | E28: =-Calculations!$D$7 -> -532.95421 | G28: =-Calculations!$L$7/12 -> -34.596774 | I28: =-Calculations!$N$7/2 -> -200 | L28: =SUM(E28:K28) -> -767.55099 | M28: =L28/(1+$B$4/12)^D28 -> -680.96024
C29: 3 | D29: 25 | E29: =-Calculations!$D$7 -> -532.95421 | G29: =-Calculations!$L$7/12 -> -34.596774 | H29: =sum(B9,B6) -> -459.17 | L29: =SUM(E29:K29) -> -1026.721 | M29: =L29/(1+$B$4/12)^D29 -> -906.36034
C30: 3 | D30: 26 | E30: =-Calculations!$D$7 -> -532.95421 | G30: =-Calculations!$L$7/12 -> -34.596774 | L30: =SUM(E30:K30) -> -567.55099 | M30: =L30/(1+$B$4/12)^D30 -> -498.52538
C31: 3 | D31: 27 | E31: =-Calculations!$D$7 -> -532.95421 | G31: =-Calculations!$L$7/12 -> -34.596774 | L31: =SUM(E31:K31) -> -567.55099 | M31: =L31/(1+$B$4/12)^D31 -> -496.04516
C32: 3 | D32: 28 | E32: =-Calculations!$D$7 -> -532.95421 | G32: =-Calculations!$L$7/12 -> -34.596774 | L32: =SUM(E32:K32) -> -567.55099 | M32: =L32/(1+$B$4/12)^D32 -> -493.57727
C33: 3 | D33: 29 | E33: =-Calculations!$D$7 -> -532.95421 | G33: =-Calculations!$L$7/12 -> -34.596774 | L33: =SUM(E33:K33) -> -567.55099 | M33: =L33/(1+$B$4/12)^D33 -> -491.12166
C34: 3 | D34: 30 | E34: =-Calculations!$D$7 -> -532.95421 | G34: =-Calculations!$L$7/12 -> -34.596774 | I34: =-Calculations!$N$7/2 -> -200 | L34: =SUM(E34:K34) -> -767.55099 | M34: =L34/(1+$B$4/12)^D34 -> -660.88422
C35: 3 | D35: 31 | E35: =-Calculations!$D$7 -> -532.95421 | G35: =-Calculations!$L$7/12 -> -34.596774 | L35: =SUM(E35:K35) -> -567.55099 | M35: =L35/(1+$B$4/12)^D35 -> -486.24704
C36: 3 | D36: 32 | E36: =-Calculations!$D$7 -> -532.95421 | G36: =-Calculations!$L$7/12 -> -34.596774 | L36: =SUM(E36:K36) -> -567.55099 | M36: =L36/(1+$B$4/12)^D36 -> -483.8279
C37: 3 | D37: 33 | E37: =-Calculations!$D$7 -> -532.95421 | G37: =-Calculations!$L$7/12 -> -34.596774 | L37: =SUM(E37:K37) -> -567.55099 | M37: =L37/(1+$B$4/12)^D37 -> -481.42079
C38: 3 | D38: 34 | E38: =-Calculations!$D$7 -> -532.95421 | G38: =-Calculations!$L$7/12 -> -34.596774 | L38: =SUM(E38:K38) -> -567.55099 | M38: =L38/(1+$B$4/12)^D38 -> -479.02567
C39: 3 | D39: 35 | E39: =-Calculations!$D$7 -> -532.95421 | G39: =-Calculations!$L$7/12 -> -34.596774 | L39: =SUM(E39:K39) -> -567.55099 | M39: =L39/(1+$B$4/12)^D39 -> -476.64245
C40: 3 | D40: 36 | E40: =-Calculations!$D$7 -> -532.95421 | G40: =-Calculations!$L$7/12 -> -34.596774 | I40: =-Calculations!$N$7/2 -> -200 | L40: =SUM(E40:K40) -> -767.55099 | M40: =L40/(1+$B$4/12)^D40 -> -641.40008
...

Sheet Risk Graphs
A1: Fit Analysis for Purchase Price Std Dev
A25: Final NPV for each vehicle plotted, further right is better
A61: Ex. Chart: For each salvage value I put on a normal distribution where the std dev is about 10% of the nominal value, this shows that we may not necessarily get the full value when selling the car, or maybe we get lucky and find a sucker who will overpay
A86: Ex. Chart: I applied the "Pert" distribution to each annual maintenance cost, maybe get unlucky and need some new tires or other high ticket items at a regular service
A113: Ex. Chart: I used another Pert distribution to consider that the manufacturer lied to me and we will likely get worse range from each vehicle, i used the same offsets for each vehicle, max is +20 from nominal, and min is -60 from nominal
A138: Ex. Chart: Used a typical uniform chart for all fuel/electricity costs, considered prices may dip to 3.10 or jump up to 4 in this example, this is just to conisder that prices can go up or down throughout time but may end up hovering overall
A163: Ex. Chart: Used another uniform chart for the vehicle loan interest rate, varying rate between 9.9 and 12.1%
A188: Ex. Chart: Another uniform series on the amount of days we commute to work, from 240-260, maybe we take some sick days or go on vacation?
A212: Ex. Chart: Applied a normal distribution to the weekend travel range, because not every trip is the same.
A237: Ex. Chart: Another Pert series on weekend trips, this could have been a normal distribution, but maybe we err on the side of a few plans getting canceled throughout a year
A262: The effects of our travel and gas variables on the annual fuel cost, further left is better!
